<robot name="onshape">
<link name="palm">
<visual>
<origin xyz="-0.0688219 0.0550506 -0.0325222" rpy="0.0102378 0.00983617 -1.58394" />
<geometry>
<mesh filename="package://palm.stl"/>
</geometry>
<material name="palm_material">
<color rgba="0.615686 0.811765 0.929412 1.0"/>
</material>
</visual>
<collision>
<origin xyz="-0.0688219 0.0550506 -0.0325222" rpy="0.0102378 0.00983617 -1.58394" />
<geometry>
<mesh filename="package://palm.stl"/>
</geometry>
<material name="palm_material">
<color rgba="0.615686 0.811765 0.929412 1.0"/>
</material>
</collision>
<inertial>
<origin xyz="-0.0183651 0.0616903 -0.0259341" rpy="0 0 0"/>
<mass value="0.706265" />
<inertia ixx="0.000380252" ixy="-3.5924e-05"  ixz="-5.03389e-06" iyy="0.000566099" iyz="3.36587e-06" izz="0.000929288" />
</inertial>
</link>

<link name="index/ring">
<visual>
<origin xyz="0.032 -0.006 0.06005" rpy="-1.5708 4.99134e-16 1.37208e-15" />
<geometry>
<mesh filename="package://part_5.stl"/>
</geometry>
<material name="part_5_material">
<color rgba="0.917647 0.917647 0.917647 1.0"/>
</material>
</visual>
<collision>
<origin xyz="0.032 -0.006 0.06005" rpy="-1.5708 4.99134e-16 1.37208e-15" />
<geometry>
<mesh filename="package://part_5.stl"/>
</geometry>
<material name="part_5_material">
<color rgba="0.917647 0.917647 0.917647 1.0"/>
</material>
</collision>
<visual>
<origin xyz="0.047 -0.006 0.06" rpy="-1.5708 -1.14201e-17 5.02959e-20" />
<geometry>
<mesh filename="package://part_6.stl"/>
</geometry>
<material name="part_6_material">
<color rgba="0.768627 0.886275 0.952941 1.0"/>
</material>
</visual>
<collision>
<origin xyz="0.047 -0.006 0.06" rpy="-1.5708 -1.14201e-17 5.02959e-20" />
<geometry>
<mesh filename="package://part_6.stl"/>
</geometry>
<material name="part_6_material">
<color rgba="0.768627 0.886275 0.952941 1.0"/>
</material>
</collision>
<visual>
<origin xyz="0.015 -0.006 0.06" rpy="-1.5708 -5.38174e-16 2.07021e-15" />
<geometry>
<mesh filename="package://part_4.stl"/>
</geometry>
<material name="part_4_material">
<color rgba="0.231373 0.380392 0.705882 1.0"/>
</material>
</visual>
<collision>
<origin xyz="0.015 -0.006 0.06" rpy="-1.5708 -5.38174e-16 2.07021e-15" />
<geometry>
<mesh filename="package://part_4.stl"/>
</geometry>
<material name="part_4_material">
<color rgba="0.231373 0.380392 0.705882 1.0"/>
</material>
</collision>
<inertial>
<origin xyz="0.0420304 -3.9953e-17 -0.00398562" rpy="0 0 0"/>
<mass value="0.126907" />
<inertia ixx="5.19935e-06" ixy="2.07858e-19"  ixz="-2.09339e-08" iyy="8.4282e-05" iyz="1.21977e-20" izz="8.19702e-05" />
</inertial>
</link>

<joint name="rev1" type="revolute">
<origin xyz="0.0294977 0.0242499 -0.0258011" rpy="1.58287 -0.0074698 -0.264539" />
<parent link="palm" />
<child link="index/ring" />
<axis xyz="0 0 1"/>
<limit effort="1" velocity="20" lower="0" upper="1.85005"/>
<joint_properties friction="0.0"/>
</joint>

<link name="part_9">
<visual>
<origin xyz="0.057 -0.006 0.035" rpy="-1.5708 -6.39918e-19 4.277e-19" />
<geometry>
<mesh filename="package://part_9.stl"/>
</geometry>
<material name="part_9_material">
<color rgba="0.980392 0.713725 0.00392157 1.0"/>
</material>
</visual>
<collision>
<origin xyz="0.057 -0.006 0.035" rpy="-1.5708 -6.39918e-19 4.277e-19" />
<geometry>
<mesh filename="package://part_9.stl"/>
</geometry>
<material name="part_9_material">
<color rgba="0.980392 0.713725 0.00392157 1.0"/>
</material>
</collision>
<inertial>
<origin xyz="0.025 1.73472e-18 -0.004" rpy="0 0 0"/>
<mass value="0.0783556" />
<inertia ixx="3.4663e-06" ixy="-3.71722e-24"  ixz="4.46838e-24" iyy="2.07085e-05" iyz="-3.76614e-23" izz="1.90379e-05" />
</inertial>
</link>

<link name="part_8">
<visual>
<origin xyz="-0.007 -0.006 0.03505" rpy="-1.5708 -2.88445e-16 -2.15802e-18" />
<geometry>
<mesh filename="package://part_8.stl"/>
</geometry>
<material name="part_8_material">
<color rgba="0.498039 0.498039 0.498039 1.0"/>
</material>
</visual>
<collision>
<origin xyz="-0.007 -0.006 0.03505" rpy="-1.5708 -2.88445e-16 -2.15802e-18" />
<geometry>
<mesh filename="package://part_8.stl"/>
</geometry>
<material name="part_8_material">
<color rgba="0.498039 0.498039 0.498039 1.0"/>
</material>
</collision>
<inertial>
<origin xyz="0.015 1.73472e-18 -0.00395" rpy="0 0 0"/>
<mass value="0.0394987" />
<inertia ixx="1.16739e-06" ixy="-9.19477e-22"  ixz="-8.98354e-24" iyy="4.35071e-06" iyz="-8.05354e-25" izz="4.05006e-06" />
</inertial>
</link>

<link name="part_7">
<visual>
<origin xyz="-0.052 -0.006 0.035" rpy="-1.5708 -7.12816e-19 -2.15704e-18" />
<geometry>
<mesh filename="package://part_7.stl"/>
</geometry>
<material name="part_7_material">
<color rgba="0.972549 0.529412 0.00392157 1.0"/>
</material>
</visual>
<collision>
<origin xyz="-0.052 -0.006 0.035" rpy="-1.5708 -7.12816e-19 -2.15704e-18" />
<geometry>
<mesh filename="package://part_7.stl"/>
</geometry>
<material name="part_7_material">
<color rgba="0.972549 0.529412 0.00392157 1.0"/>
</material>
</collision>
<inertial>
<origin xyz="0.00956014 -5.20417e-18 -0.004" rpy="0 0 0"/>
<mass value="0.0317674" />
<inertia ixx="1.42991e-06" ixy="-2.90636e-24"  ixz="-4.52714e-24" iyy="2.58487e-06" iyz="4.27301e-24" izz="1.90344e-06" />
</inertial>
</link>

<joint name="middle_rev1" type="revolute">
<origin xyz="0.03 -6.93889e-18 -1.38778e-17" rpy="1.30118e-16 5.49449e-16 4.26562e-12" />
<parent link="part_8" />
<child link="part_7" />
<axis xyz="0 0 1"/>
<limit effort="1" velocity="20" lower="-1.85005" upper="0"/>
<joint_properties friction="0.0"/>
</joint>

<joint name="middle_rev2" type="revolute">
<origin xyz="0.05 6.245e-17 -1.17961e-16" rpy="-5.76818e-17 6.57175e-17 4.58361e-16" />
<parent link="part_9" />
<child link="part_8" />
<axis xyz="0 0 1"/>
<limit effort="1" velocity="20" lower="-1.85005" upper="0"/>
<joint_properties friction="0.0"/>
</joint>

<joint name="rev2" type="revolute">
<origin xyz="0.0340496 0.0496789 -0.0255073" rpy="1.58063 0.00839911 -0.0130604" />
<parent link="palm" />
<child link="part_9" />
<axis xyz="0 0 1"/>
<limit effort="1" velocity="20" lower="-0.279253" upper="1.5708"/>
<joint_properties friction="0.0"/>
</joint>

<link name="index/ring_2">
<visual>
<origin xyz="0.015 -0.006 0.06" rpy="-1.5708 -5.62929e-15 6.32704e-14" />
<geometry>
<mesh filename="package://part_4.stl"/>
</geometry>
<material name="part_4_material">
<color rgba="0.231373 0.380392 0.705882 1.0"/>
</material>
</visual>
<collision>
<origin xyz="0.015 -0.006 0.06" rpy="-1.5708 -5.62929e-15 6.32704e-14" />
<geometry>
<mesh filename="package://part_4.stl"/>
</geometry>
<material name="part_4_material">
<color rgba="0.231373 0.380392 0.705882 1.0"/>
</material>
</collision>
<visual>
<origin xyz="0.032 -0.006 0.06005" rpy="-1.5708 9.26671e-16 6.30137e-14" />
<geometry>
<mesh filename="package://part_5.stl"/>
</geometry>
<material name="part_5_material">
<color rgba="0.917647 0.917647 0.917647 1.0"/>
</material>
</visual>
<collision>
<origin xyz="0.032 -0.006 0.06005" rpy="-1.5708 9.26671e-16 6.30137e-14" />
<geometry>
<mesh filename="package://part_5.stl"/>
</geometry>
<material name="part_5_material">
<color rgba="0.917647 0.917647 0.917647 1.0"/>
</material>
</collision>
<visual>
<origin xyz="0.047 -0.006 0.06" rpy="-1.5708 7.01309e-18 -6.711e-19" />
<geometry>
<mesh filename="package://part_6.stl"/>
</geometry>
<material name="part_6_material">
<color rgba="0.768627 0.886275 0.952941 1.0"/>
</material>
</visual>
<collision>
<origin xyz="0.047 -0.006 0.06" rpy="-1.5708 7.01309e-18 -6.711e-19" />
<geometry>
<mesh filename="package://part_6.stl"/>
</geometry>
<material name="part_6_material">
<color rgba="0.768627 0.886275 0.952941 1.0"/>
</material>
</collision>
<inertial>
<origin xyz="0.0420304 7.11121e-16 -0.00398562" rpy="0 0 0"/>
<mass value="0.126907" />
<inertia ixx="5.19935e-06" ixy="-2.38415e-18"  ixz="-2.09339e-08" iyy="8.4282e-05" iyz="-6.54057e-21" izz="8.19702e-05" />
</inertial>
</link>

<joint name="rev3" type="revolute">
<origin xyz="0.0321351 0.0754417 -0.0252772" rpy="1.57778 -0.0123618 0.238064" />
<parent link="palm" />
<child link="index/ring_2" />
<axis xyz="0 0 1"/>
<limit effort="1" velocity="20" lower="0" upper="1.85005"/>
<joint_properties friction="0.0"/>
</joint>

<link name="pinky">
<visual>
<origin xyz="0.041 -0.006 0.013" rpy="-1.5708 -2.40132e-16 6.71055e-18" />
<geometry>
<mesh filename="package://part_12.stl"/>
</geometry>
<material name="part_12_material">
<color rgba="0.231373 0.380392 0.705882 1.0"/>
</material>
</visual>
<collision>
<origin xyz="0.041 -0.006 0.013" rpy="-1.5708 -2.40132e-16 6.71055e-18" />
<geometry>
<mesh filename="package://part_12.stl"/>
</geometry>
<material name="part_12_material">
<color rgba="0.231373 0.380392 0.705882 1.0"/>
</material>
</collision>
<visual>
<origin xyz="0.00400006 -0.00600032 0.013" rpy="-1.5708 4.79413e-14 1.06593e-05" />
<geometry>
<mesh filename="package://part_10.stl"/>
</geometry>
<material name="part_10_material">
<color rgba="0.615686 0.811765 0.929412 1.0"/>
</material>
</visual>
<collision>
<origin xyz="0.00400006 -0.00600032 0.013" rpy="-1.5708 4.79413e-14 1.06593e-05" />
<geometry>
<mesh filename="package://part_10.stl"/>
</geometry>
<material name="part_10_material">
<color rgba="0.615686 0.811765 0.929412 1.0"/>
</material>
</collision>
<visual>
<origin xyz="0.0170001 -0.00600018 0.01305" rpy="-1.5708 4.8058e-14 1.06593e-05" />
<geometry>
<mesh filename="package://part_11.stl"/>
</geometry>
<material name="part_11_material">
<color rgba="0.647059 0.647059 0.647059 1.0"/>
</material>
</visual>
<collision>
<origin xyz="0.0170001 -0.00600018 0.01305" rpy="-1.5708 4.8058e-14 1.06593e-05" />
<geometry>
<mesh filename="package://part_11.stl"/>
</geometry>
<material name="part_11_material">
<color rgba="0.647059 0.647059 0.647059 1.0"/>
</material>
</collision>
<inertial>
<origin xyz="0.0361747 1.07659e-07 -0.00398448" rpy="0 0 0"/>
<mass value="0.0778902" />
<inertia ixx="2.29261e-06" ixy="-1.79055e-10"  ixz="-1.06492e-08" iyy="3.6447e-05" iyz="-1.15956e-14" izz="3.59007e-05" />
</inertial>
</link>

<joint name="rev4" type="revolute">
<origin xyz="0.0238746 0.0999199 -0.0251253" rpy="1.5745 0.0777277 0.48972" />
<parent link="palm" />
<child link="pinky" />
<axis xyz="0 0 1"/>
<limit effort="1" velocity="20" lower="-1.76278" upper="0"/>
<joint_properties friction="0.0"/>
</joint>

<link name="thumb">
<visual>
<origin xyz="0.052 -0.09 -0.00205" rpy="-1.09862e-18 -5.33997e-18 6.12655e-19" />
<geometry>
<mesh filename="package://part_3.stl"/>
</geometry>
<material name="part_3_material">
<color rgba="0.917647 0.917647 0.917647 1.0"/>
</material>
</visual>
<collision>
<origin xyz="0.052 -0.09 -0.00205" rpy="-1.09862e-18 -5.33997e-18 6.12655e-19" />
<geometry>
<mesh filename="package://part_3.stl"/>
</geometry>
<material name="part_3_material">
<color rgba="0.917647 0.917647 0.917647 1.0"/>
</material>
</collision>
<visual>
<origin xyz="-0.06 -0.09005 0.00995" rpy="3.14159 4.19954e-17 -3.14159" />
<geometry>
<mesh filename="package://part_2.stl"/>
</geometry>
<material name="part_2_material">
<color rgba="0.647059 0.647059 0.647059 1.0"/>
</material>
</visual>
<collision>
<origin xyz="-0.06 -0.09005 0.00995" rpy="3.14159 4.19954e-17 -3.14159" />
<geometry>
<mesh filename="package://part_2.stl"/>
</geometry>
<material name="part_2_material">
<color rgba="0.647059 0.647059 0.647059 1.0"/>
</material>
</collision>
<visual>
<origin xyz="-0.046 0.09 -0.00205" rpy="-1.96777e-18 1.77032e-13 -3.14159" />
<geometry>
<mesh filename="package://part_1.stl"/>
</geometry>
<material name="part_1_material">
<color rgba="0.615686 0.811765 0.929412 1.0"/>
</material>
</visual>
<collision>
<origin xyz="-0.046 0.09 -0.00205" rpy="-1.96777e-18 1.77032e-13 -3.14159" />
<geometry>
<mesh filename="package://part_1.stl"/>
</geometry>
<material name="part_1_material">
<color rgba="0.615686 0.811765 0.929412 1.0"/>
</material>
</collision>
<inertial>
<origin xyz="-0.0489481 -1.73834e-05 0.00395" rpy="0 0 0"/>
<mass value="0.147389" />
<inertia ixx="6.66851e-06" ixy="-3.9761e-09"  ixz="-3.45113e-18" iyy="0.000104209" iyz="3.28374e-21" izz="0.000107341" />
</inertial>
</link>

<joint name="rev5" type="revolute">
<origin xyz="-0.0515159 0.0192692 -0.0266893" rpy="-1.58424 -0.00457455 1.99497" />
<parent link="palm" />
<child link="thumb" />
<axis xyz="0 0 1"/>
<limit effort="1" velocity="20" lower="-1.5708" upper="0"/>
<joint_properties friction="0.0"/>
</joint>


</robot>
