<?xml version="1.0" encoding="utf-8"?>
<robot name="onshape">
    <link name="part_1">
        <visual>
            <origin xyz="-0.00893093 -0.0203919 0.0193023" rpy="1.28146e-24 3.88578e-16 3.79656e-25" />
            <geometry>
                <mesh filename="package://part_1.stl"/>
            </geometry>
            <!-- <material name="part_1_material"> -->
            <!--     <color rgba="0.615686 0.811765 0.929412 1.0"/> -->
            <!-- </material> -->
        </visual>
        <collision>
            <origin xyz="-0.00893093 -0.0203919 0.0193023" rpy="1.28146e-24 3.88578e-16 3.79656e-25" />
            <geometry>
                <mesh filename="package://part_1.stl"/>
            </geometry>
            <!-- <material name="part_1_material"> -->
            <!--     <color rgba="0.615686 0.811765 0.929412 1.0"/> -->
            <!-- </material> -->
        </collision>
        <!-- <inertial> -->
        <!--     <origin xyz="0 0 0" rpy="0 0 0"/> -->
        <!--     <mass value="0" /> -->
        <!--     <inertia ixx="0" ixy="0"  ixz="0" iyy="0" iyz="0" izz="0" /> -->
        <!-- </inertial> -->
    </link>

    <link name="part_2">
        <visual>
            <origin xyz="0.008 0.0345 -0.0395007" rpy="1.5708 -3.49429e-42 -5.19926e-32" />
            <geometry>
                <mesh filename="package://part_2.stl"/>
            </geometry>
            <!-- <material name="part_2_material"> -->
            <!--     <color rgba="0.231373 0.380392 0.705882 1.0"/> -->
            <!-- </material> -->
        </visual>
        <collision>
            <origin xyz="0.008 0.0345 -0.0395007" rpy="1.5708 -3.49429e-42 -5.19926e-32" />
            <geometry>
                <mesh filename="package://part_2.stl"/>
            </geometry>
            <!-- <material name="part_2_material"> -->
            <!--     <color rgba="0.231373 0.380392 0.705882 1.0"/> -->
            <!-- </material> -->
        </collision>
        <!-- <inertial> -->
        <!--     <origin xyz="0 0 0" rpy="0 0 0"/> -->
        <!--     <mass value="0" /> -->
        <!--     <inertia ixx="0" ixy="0"  ixz="0" iyy="0" iyz="0" izz="0" /> -->
        <!-- </inertial> -->
    </link>

    <joint name="base" type="revolute">
        <origin xyz="-0.00893093 -0.0168919 0.0093023" rpy="-1.5708 4.39586e-16 -2.39529e-25" />
        <parent link="part_1" />
        <child link="part_2" />
        <axis xyz="0 0 1"/>
        <limit effort="1000" velocity="100" lower="-1.5" upper="1.5"/>
        <!-- <joint_properties friction="0.0"/> -->
    </joint>

    <!-- <link name="part_3"> -->
    <!--     <visual> -->
    <!--         <origin xyz="-2.38769e-05 -0.0345 0.0660641" rpy="-1.5708 -0 0" /> -->
    <!--         <geometry> -->
    <!--             <mesh filename="package://part_3.stl"/> -->
    <!--         </geometry> -->
    <!--         <material name="part_3_material"> -->
    <!--             <color rgba="0.917647 0.917647 0.917647 1.0"/> -->
    <!--         </material> -->
    <!--     </visual> -->
    <!--     <collision> -->
    <!--         <origin xyz="-2.38769e-05 -0.0345 0.0660641" rpy="-1.5708 -0 0" /> -->
    <!--         <geometry> -->
    <!--             <mesh filename="package://part_3.stl"/> -->
    <!--         </geometry> -->
    <!--         <material name="part_3_material"> -->
    <!--             <color rgba="0.917647 0.917647 0.917647 1.0"/> -->
    <!--         </material> -->
    <!--     </collision> -->
    <!--     <inertial> -->
    <!--         <origin xyz="0 0 0" rpy="0 0 0"/> -->
    <!--         <mass value="0" /> -->
    <!--         <inertia ixx="0" ixy="0"  ixz="0" iyy="0" iyz="0" izz="0" /> -->
    <!--     </inertial> -->
    <!-- </link> -->

    <!-- <joint name="notbase" type="revolute"> -->
    <!--     <origin xyz="-8.67362e-18 0.0445 -0.00675" rpy="3.14159 -2.39529e-25 -4.39586e-16" /> -->
    <!--     <parent link="part_2" /> -->
    <!--     <child link="part_3" /> -->
    <!--     <axis xyz="0 0 1"/> -->
    <!--     <limit effort="1" velocity="20" lower="-1.5708" upper="0"/> -->
    <!--     <joint_properties friction="0.0"/> -->
    <!-- </joint> -->
</robot>
