<robot name="onshape">
<link name="middle">
<visual>
<origin xyz="0.0903634 0.0348014 -0.0257872" rpy="0.00983668 -0.0102373 -0.0132438" />
<geometry>
<mesh filename="package://part_7.stl"/>
</geometry>
<material name="part_7_material">
<color rgba="0.972549 0.529412 0.00392157 1.0"/>
</material>
</visual>
<collision>
<origin xyz="0.0903634 0.0348014 -0.0257872" rpy="0.00983668 -0.0102373 -0.0132438" />
<geometry>
<mesh filename="package://part_7.stl"/>
</geometry>
<material name="part_7_material">
<color rgba="0.972549 0.529412 0.00392157 1.0"/>
</material>
</collision>
<visual>
<origin xyz="0.105361 0.0345528 -0.0256341" rpy="0.00983668 -0.0102373 -0.0132438" />
<geometry>
<mesh filename="package://part_8.stl"/>
</geometry>
<material name="part_8_material">
<color rgba="0.498039 0.498039 0.498039 1.0"/>
</material>
</visual>
<collision>
<origin xyz="0.105361 0.0345528 -0.0256341" rpy="0.00983668 -0.0102373 -0.0132438" />
<geometry>
<mesh filename="package://part_8.stl"/>
</geometry>
<material name="part_8_material">
<color rgba="0.498039 0.498039 0.498039 1.0"/>
</material>
</collision>
<visual>
<origin xyz="0.119359 0.0344173 -0.0254903" rpy="0.00983668 -0.0102373 -0.0132438" />
<geometry>
<mesh filename="package://part_9.stl"/>
</geometry>
<material name="part_9_material">
<color rgba="0.980392 0.713725 0.00392157 1.0"/>
</material>
</visual>
<collision>
<origin xyz="0.119359 0.0344173 -0.0254903" rpy="0.00983668 -0.0102373 -0.0132438" />
<geometry>
<mesh filename="package://part_9.stl"/>
</geometry>
<material name="part_9_material">
<color rgba="0.980392 0.713725 0.00392157 1.0"/>
</material>
</collision>
<inertial>
<origin xyz="0.112078 0.0734431 -0.0191866" rpy="0 0 0"/>
<mass value="0.149622" />
<inertia ixx="6.10018e-06" ixy="1.20593e-06"  ixz="-8.76648e-07" iyy="0.000132464" iyz="4.35536e-08" izz="0.000135125" />
</inertial>
</link>

<link name="part_1">
<visual>
<origin xyz="-0.103 -0.006 -0.00395" rpy="-1.5708 -1.5708 0" />
<geometry>
<mesh filename="package://part_1.stl"/>
</geometry>
<material name="part_1_material">
<color rgba="0.615686 0.811765 0.929412 1.0"/>
</material>
</visual>
<collision>
<origin xyz="-0.103 -0.006 -0.00395" rpy="-1.5708 -1.5708 0" />
<geometry>
<mesh filename="package://part_1.stl"/>
</geometry>
<material name="part_1_material">
<color rgba="0.615686 0.811765 0.929412 1.0"/>
</material>
</collision>
<inertial>
<origin xyz="-0.0525707 4.33681e-18 -0.0113167" rpy="0 0 0"/>
<mass value="0.706265" />
<inertia ixx="0.000929372" ixy="-2.17059e-22"  ixz="-7.64153e-22" iyy="0.000566979" iyz="3.34174e-05" izz="0.000379288" />
</inertial>
</link>

<link name="index/ring">
<visual>
<origin xyz="0.032 -0.006 0.06005" rpy="-1.5708 -8.21487e-15 5.26416e-15" />
<geometry>
<mesh filename="package://part_5.stl"/>
</geometry>
<material name="part_5_material">
<color rgba="0.917647 0.917647 0.917647 1.0"/>
</material>
</visual>
<collision>
<origin xyz="0.032 -0.006 0.06005" rpy="-1.5708 -8.21487e-15 5.26416e-15" />
<geometry>
<mesh filename="package://part_5.stl"/>
</geometry>
<material name="part_5_material">
<color rgba="0.917647 0.917647 0.917647 1.0"/>
</material>
</collision>
<visual>
<origin xyz="0.047 -0.006 0.06" rpy="-1.5708 -2.58862e-17 1.51075e-18" />
<geometry>
<mesh filename="package://part_6.stl"/>
</geometry>
<material name="part_6_material">
<color rgba="0.768627 0.886275 0.952941 1.0"/>
</material>
</visual>
<collision>
<origin xyz="0.047 -0.006 0.06" rpy="-1.5708 -2.58862e-17 1.51075e-18" />
<geometry>
<mesh filename="package://part_6.stl"/>
</geometry>
<material name="part_6_material">
<color rgba="0.768627 0.886275 0.952941 1.0"/>
</material>
</collision>
<visual>
<origin xyz="0.015 -0.006 0.06" rpy="-1.5708 -8.03295e-15 5.39772e-15" />
<geometry>
<mesh filename="package://part_4.stl"/>
</geometry>
<material name="part_4_material">
<color rgba="0.231373 0.380392 0.705882 1.0"/>
</material>
</visual>
<collision>
<origin xyz="0.015 -0.006 0.06" rpy="-1.5708 -8.03295e-15 5.39772e-15" />
<geometry>
<mesh filename="package://part_4.stl"/>
</geometry>
<material name="part_4_material">
<color rgba="0.231373 0.380392 0.705882 1.0"/>
</material>
</collision>
<inertial>
<origin xyz="0.0420304 3.85531e-17 -0.00398562" rpy="0 0 0"/>
<mass value="0.126907" />
<inertia ixx="5.19935e-06" ixy="-1.97658e-19"  ixz="-2.09339e-08" iyy="8.4282e-05" iyz="6.49077e-21" izz="8.19702e-05" />
</inertial>
</link>

<joint name="rev1" type="revolute">
<origin xyz="-0.00421747 3.46945e-18 0.0254883" rpy="1.69485e-15 -0.251301 -7.99298e-17" />
<parent link="part_1" />
<child link="index/ring" />
<axis xyz="0 0 1"/>
<limit effort="1" velocity="20" lower="0" upper="1.85005"/>
<joint_properties friction="0.0"/>
</joint>

<link name="index/ring_2">
<visual>
<origin xyz="0.015 -0.006 0.06" rpy="-1.5708 8.64061e-16 1.51752e-14" />
<geometry>
<mesh filename="package://part_4.stl"/>
</geometry>
<material name="part_4_material">
<color rgba="0.231373 0.380392 0.705882 1.0"/>
</material>
</visual>
<collision>
<origin xyz="0.015 -0.006 0.06" rpy="-1.5708 8.64061e-16 1.51752e-14" />
<geometry>
<mesh filename="package://part_4.stl"/>
</geometry>
<material name="part_4_material">
<color rgba="0.231373 0.380392 0.705882 1.0"/>
</material>
</collision>
<visual>
<origin xyz="0.032 -0.006 0.06005" rpy="-1.5708 -2.08847e-15 9.43728e-15" />
<geometry>
<mesh filename="package://part_5.stl"/>
</geometry>
<material name="part_5_material">
<color rgba="0.917647 0.917647 0.917647 1.0"/>
</material>
</visual>
<collision>
<origin xyz="0.032 -0.006 0.06005" rpy="-1.5708 -2.08847e-15 9.43728e-15" />
<geometry>
<mesh filename="package://part_5.stl"/>
</geometry>
<material name="part_5_material">
<color rgba="0.917647 0.917647 0.917647 1.0"/>
</material>
</collision>
<visual>
<origin xyz="0.047 -0.006 0.06" rpy="-1.5708 -6.02584e-18 -3.76452e-19" />
<geometry>
<mesh filename="package://part_6.stl"/>
</geometry>
<material name="part_6_material">
<color rgba="0.768627 0.886275 0.952941 1.0"/>
</material>
</visual>
<collision>
<origin xyz="0.047 -0.006 0.06" rpy="-1.5708 -6.02584e-18 -3.76452e-19" />
<geometry>
<mesh filename="package://part_6.stl"/>
</geometry>
<material name="part_6_material">
<color rgba="0.768627 0.886275 0.952941 1.0"/>
</material>
</collision>
<inertial>
<origin xyz="0.0420304 9.70873e-17 -0.00398562" rpy="0 0 0"/>
<mass value="0.126907" />
<inertia ixx="5.19935e-06" ixy="-3.026e-19"  ixz="-2.09339e-08" iyy="8.4282e-05" iyz="-9.35063e-21" izz="8.19702e-05" />
</inertial>
</link>

<joint name="rev2" type="revolute">
<origin xyz="-0.00225303 3.81639e-17 -0.0257365" rpy="-4.4004e-15 0.251301 1.60222e-16" />
<parent link="part_1" />
<child link="index/ring_2" />
<axis xyz="0 0 1"/>
<limit effort="1" velocity="20" lower="0" upper="1.85005"/>
<joint_properties friction="0.0"/>
</joint>

<link name="pinky">
<visual>
<origin xyz="0.041 -0.006 0.013" rpy="-1.5708 -1.52984e-16 -4.88096e-19" />
<geometry>
<mesh filename="package://part_12.stl"/>
</geometry>
<material name="part_12_material">
<color rgba="0.231373 0.380392 0.705882 1.0"/>
</material>
</visual>
<collision>
<origin xyz="0.041 -0.006 0.013" rpy="-1.5708 -1.52984e-16 -4.88096e-19" />
<geometry>
<mesh filename="package://part_12.stl"/>
</geometry>
<material name="part_12_material">
<color rgba="0.231373 0.380392 0.705882 1.0"/>
</material>
</collision>
<visual>
<origin xyz="0.0043727 -0.00863842 0.013" rpy="-1.5708 -6.77174e-15 0.0509103" />
<geometry>
<mesh filename="package://part_10.stl"/>
</geometry>
<material name="part_10_material">
<color rgba="0.615686 0.811765 0.929412 1.0"/>
</material>
</visual>
<collision>
<origin xyz="0.0043727 -0.00863842 0.013" rpy="-1.5708 -6.77174e-15 0.0509103" />
<geometry>
<mesh filename="package://part_10.stl"/>
</geometry>
<material name="part_10_material">
<color rgba="0.615686 0.811765 0.929412 1.0"/>
</material>
</collision>
<visual>
<origin xyz="0.017 -0.006 0.01305" rpy="-1.5708 2.8771e-15 -5.7637e-16" />
<geometry>
<mesh filename="package://part_11.stl"/>
</geometry>
<material name="part_11_material">
<color rgba="0.647059 0.647059 0.647059 1.0"/>
</material>
</visual>
<collision>
<origin xyz="0.017 -0.006 0.01305" rpy="-1.5708 2.8771e-15 -5.7637e-16" />
<geometry>
<mesh filename="package://part_11.stl"/>
</geometry>
<material name="part_11_material">
<color rgba="0.647059 0.647059 0.647059 1.0"/>
</material>
</collision>
<inertial>
<origin xyz="0.0361724 9.01004e-05 -0.00398448" rpy="0 0 0"/>
<mass value="0.0778902" />
<inertia ixx="2.29537e-06" ixy="-1.94692e-07"  ixz="4.16477e-10" iyy="3.64371e-05" iyz="1.08911e-10" izz="3.58924e-05" />
</inertial>
</link>

<joint name="rev4" type="revolute">
<origin xyz="-0.010835 6.245e-17 -0.0501043" rpy="-1.33511e-15 0.502601 -1.42695e-16" />
<parent link="part_1" />
<child link="pinky" />
<axis xyz="0 0 1"/>
<limit effort="1" velocity="20" lower="-1.76278" upper="0"/>
<joint_properties friction="0.0"/>
</joint>

<link name="thumb">
<visual>
<origin xyz="0.052 -0.09 -0.00205" rpy="1.8857e-18 -5.90873e-17 -5.02194e-19" />
<geometry>
<mesh filename="package://part_3.stl"/>
</geometry>
<material name="part_3_material">
<color rgba="0.917647 0.917647 0.917647 1.0"/>
</material>
</visual>
<collision>
<origin xyz="0.052 -0.09 -0.00205" rpy="1.8857e-18 -5.90873e-17 -5.02194e-19" />
<geometry>
<mesh filename="package://part_3.stl"/>
</geometry>
<material name="part_3_material">
<color rgba="0.917647 0.917647 0.917647 1.0"/>
</material>
</collision>
<visual>
<origin xyz="-0.0600552 -0.09005 0.00969577" rpy="3.14159 0.00940642 -3.14159" />
<geometry>
<mesh filename="package://part_2.stl"/>
</geometry>
<material name="part_2_material">
<color rgba="0.647059 0.647059 0.647059 1.0"/>
</material>
</visual>
<collision>
<origin xyz="-0.0600552 -0.09005 0.00969577" rpy="3.14159 0.00940642 -3.14159" />
<geometry>
<mesh filename="package://part_2.stl"/>
</geometry>
<material name="part_2_material">
<color rgba="0.647059 0.647059 0.647059 1.0"/>
</material>
</collision>
<visual>
<origin xyz="-0.045943 0.09 -0.00217202" rpy="1.74942e-15 0.00940642 3.14159" />
<geometry>
<mesh filename="package://part_1.stl"/>
</geometry>
<material name="part_1_material">
<color rgba="0.615686 0.811765 0.929412 1.0"/>
</material>
</visual>
<collision>
<origin xyz="-0.045943 0.09 -0.00217202" rpy="1.74942e-15 0.00940642 3.14159" />
<geometry>
<mesh filename="package://part_1.stl"/>
</geometry>
<material name="part_1_material">
<color rgba="0.615686 0.811765 0.929412 1.0"/>
</material>
</collision>
<inertial>
<origin xyz="-0.0489472 -1.73834e-05 0.00375545" rpy="0 0 0"/>
<mass value="0.147389" />
<inertia ixx="6.67394e-06" ixy="-3.97646e-09"  ixz="-6.20136e-07" iyy="0.000104208" iyz="7.67087e-11" izz="0.000107334" />
</inertial>
</link>

<joint name="rev5" type="revolute">
<origin xyz="-0.0851629 3.46945e-18 0.0315418" rpy="-2.86766e-14 1.13346 3.14159" />
<parent link="part_1" />
<child link="thumb" />
<axis xyz="0 0 1"/>
<limit effort="1" velocity="20" lower="-1.5708" upper="0"/>
<joint_properties friction="0.0"/>
</joint>

<joint name="rev3" type="revolute">
<origin xyz="0.0627651 0.0701093 -0.0197301" rpy="1.58063 -0.0102373 -0.0132438" />
<parent link="middle" />
<child link="part_1" />
<axis xyz="0 0 1"/>
<limit effort="1" velocity="20" lower="-0.279253" upper="1.5708"/>
<joint_properties friction="0.0"/>
</joint>


</robot>
