<robot name="onshape">
<link name="part_1">
<visual>
<origin xyz="-0.00893093 -0.0203919 0.0193023" rpy="1.28146e-24 3.88578e-16 3.79656e-25" />
<geometry>
<mesh filename="package://part_1.stl"/>
</geometry>
<material name="part_1_material">
<color rgba="0.615686 0.811765 0.929412 1.0"/>
</material>
</visual>
<collision>
<origin xyz="-0.00893093 -0.0203919 0.0193023" rpy="1.28146e-24 3.88578e-16 3.79656e-25" />
<geometry>
<mesh filename="package://part_1.stl"/>
</geometry>
<material name="part_1_material">
<color rgba="0.615686 0.811765 0.929412 1.0"/>
</material>
</collision>
<inertial>
<origin xyz="-0.00893084 -0.0203919 0.0236261" rpy="0 0 0"/>
<mass value="0.0694721" />
<inertia ixx="1.0641e-05" ixy="1.48765e-11"  ixz="-1.31727e-11" iyy="1.01976e-05" iyz="5.15156e-12" izz="3.44189e-06" />
</inertial>
</link>

<link name="part_2">
<visual>
<origin xyz="0.008 0.0345 -0.0395007" rpy="1.5708 -3.49429e-42 -5.19926e-32" />
<geometry>
<mesh filename="package://part_2.stl"/>
</geometry>
<material name="part_2_material">
<color rgba="0.231373 0.380392 0.705882 1.0"/>
</material>
</visual>
<collision>
<origin xyz="0.008 0.0345 -0.0395007" rpy="1.5708 -3.49429e-42 -5.19926e-32" />
<geometry>
<mesh filename="package://part_2.stl"/>
</geometry>
<material name="part_2_material">
<color rgba="0.231373 0.380392 0.705882 1.0"/>
</material>
</collision>
<inertial>
<origin xyz="-8.67362e-18 0.0244953 -0.00325" rpy="0 0 0"/>
<mass value="0.086143" />
<inertia ixx="2.22038e-05" ixy="6.30359e-47"  ixz="5.23987e-39" iyy="3.95791e-06" iyz="3.72241e-45" izz="2.20911e-05" />
</inertial>
</link>

<link name="part_3">
<visual>
<origin xyz="-2.38769e-05 -0.0345 0.0660641" rpy="-1.5708 -0 0" />
<geometry>
<mesh filename="package://part_3.stl"/>
</geometry>
<material name="part_3_material">
<color rgba="0.917647 0.917647 0.917647 1.0"/>
</material>
</visual>
<collision>
<origin xyz="-2.38769e-05 -0.0345 0.0660641" rpy="-1.5708 -0 0" />
<geometry>
<mesh filename="package://part_3.stl"/>
</geometry>
<material name="part_3_material">
<color rgba="0.917647 0.917647 0.917647 1.0"/>
</material>
</collision>
<inertial>
<origin xyz="-2.45978e-18 -0.0169445 -0.00325" rpy="0 0 0"/>
<mass value="0.0603626" />
<inertia ixx="8.6682e-06" ixy="0"  ixz="0" iyy="2.17049e-06" iyz="0" izz="9.00065e-06" />
</inertial>
</link>

<joint name="rev2" type="revolute">
<origin xyz="-8.67362e-18 0.0445 -0.00675" rpy="3.14159 -2.39529e-25 -4.39586e-16" />
<parent link="part_2" />
<child link="part_3" />
<axis xyz="0 0 1"/>
<limit effort="1" velocity="20" lower="-1.5708" upper="0"/>
<joint_properties friction="0.0"/>
</joint>

<joint name="rev1" type="revolute">
<origin xyz="-0.00893093 -0.0168919 0.0093023" rpy="-1.5708 4.39586e-16 -2.39529e-25" />
<parent link="part_1" />
<child link="part_2" />
<axis xyz="0 0 1"/>
<limit effort="1" velocity="20" lower="0" upper="1.5708"/>
<joint_properties friction="0.0"/>
</joint>


</robot>
